Workbook

Sheet Resumen
A1: Matriz de pruebas de QA
A2: Laboratorio 1: Implementación de Monolito con patrón MVC y DAO (Arquitectura de Software, Pontificia Universidad Javeriana)
A3: Responsable de QA: Santiago Hernández. Versión inicial: 26/10/2026.
A5: Indicadores generales
A6: Casos de prueba | B6: =COUNTA('Casos de prueba'!$A$2:$A$500) -> 165
A7: Aprobados | B7: =COUNTIF('Casos de prueba'!$K$2:$K$500,"Aprobado") -> 150
A8: Fallidos | B8: =COUNTIF('Casos de prueba'!$K$2:$K$500,"Fallido") -> 13
A9: Bloqueados | B9: =COUNTIF('Casos de prueba'!$K$2:$K$500,"Bloqueado") -> 2
A10: Pendientes | B10: =COUNTIF('Casos de prueba'!$K$2:$K$500,"Pendiente") -> 0
A11: No aplica | B11: =COUNTIF('Casos de prueba'!$K$2:$K$500,"No aplica") -> 0
A12: Avance de ejecución | B12: =IFERROR((B7+B8)/(B6-B11),0) -> 0.98787879
A13: Tasa de aprobación (sobre ejecutados) | B13: =IFERROR(B7/(B7+B8),0) -> 0.9202454
A14: Defectos registrados | B14: =COUNTIF(Defectos!$A$2:$A$500,"DEF-*") -> 11
A15: Defectos abiertos | B15: =COUNTIFS(Defectos!$A$2:$A$500,"DEF-*",Defectos!$J$2:$J$500,"Abierto")+COUNTIFS(Defectos!$A$2:$A$500,"DEF-*",Defectos!$J$2:$J$500,"En corrección") -> 2
A18: Cobertura por área
A19: Área | B19: Total | C19: Aprobados | D19: Fallidos | E19: Pendientes | F19: Bloqueados | G19: % aprobado
A20: Base de datos | B20: =COUNTIF('Casos de prueba'!$C$2:$C$500,A20) -> 25 | C20: =COUNTIFS('Casos de prueba'!$C$2:$C$500,A20,'Casos de prueba'!$K$2:$K$500,"Aprobado") -> 23 | D20: =COUNTIFS('Casos de prueba'!$C$2:$C$500,A20,'Casos de prueba'!$K$2:$K$500,"Fallido") -> 1 | E20: =COUNTIFS('Casos de prueba'!$C$2:$C$500,A20,'Casos de prueba'!$K$2:$K$500,"Pendiente") -> 0 | F20: =COUNTIFS('Casos de prueba'!$C$2:$C$500,A20,'Casos de prueba'!$K$2:$K$500,"Bloqueado") -> 1 | G20: =IFERROR(C20/B20,0) -> 0.92
A21: Backend y DAO | B21: =COUNTIF('Casos de prueba'!$C$2:$C$500,A21) -> 9 | C21: =COUNTIFS('Casos de prueba'!$C$2:$C$500,A21,'Casos de prueba'!$K$2:$K$500,"Aprobado") -> 8 | D21: =COUNTIFS('Casos de prueba'!$C$2:$C$500,A21,'Casos de prueba'!$K$2:$K$500,"Fallido") -> 1 | E21: =COUNTIFS('Casos de prueba'!$C$2:$C$500,A21,'Casos de prueba'!$K$2:$K$500,"Pendiente") -> 0 | F21: =COUNTIFS('Casos de prueba'!$C$2:$C$500,A21,'Casos de prueba'!$K$2:$K$500,"Bloqueado") -> 0 | G21: =IFERROR(C21/B21,0) -> 0.88888889
A22: API REST | B22: =COUNTIF('Casos de prueba'!$C$2:$C$500,A22) -> 62 | C22: =COUNTIFS('Casos de prueba'!$C$2:$C$500,A22,'Casos de prueba'!$K$2:$K$500,"Aprobado") -> 61 | D22: =COUNTIFS('Casos de prueba'!$C$2:$C$500,A22,'Casos de prueba'!$K$2:$K$500,"Fallido") -> 1 | E22: =COUNTIFS('Casos de prueba'!$C$2:$C$500,A22,'Casos de prueba'!$K$2:$K$500,"Pendiente") -> 0 | F22: =COUNTIFS('Casos de prueba'!$C$2:$C$500,A22,'Casos de prueba'!$K$2:$K$500,"Bloqueado") -> 0 | G22: =IFERROR(C22/B22,0) -> 0.98387097
A23: Swagger | B23: =COUNTIF('Casos de prueba'!$C$2:$C$500,A23) -> 9 | C23: =COUNTIFS('Casos de prueba'!$C$2:$C$500,A23,'Casos de prueba'!$K$2:$K$500,"Aprobado") -> 8 | D23: =COUNTIFS('Casos de prueba'!$C$2:$C$500,A23,'Casos de prueba'!$K$2:$K$500,"Fallido") -> 1 | E23: =COUNTIFS('Casos de prueba'!$C$2:$C$500,A23,'Casos de prueba'!$K$2:$K$500,"Pendiente") -> 0 | F23: =COUNTIFS('Casos de prueba'!$C$2:$C$500,A23,'Casos de prueba'!$K$2:$K$500,"Bloqueado") -> 0 | G23: =IFERROR(C23/B23,0) -> 0.88888889
A24: Frontend MVC | B24: =COUNTIF('Casos de prueba'!$C$2:$C$500,A24) -> 40 | C24: =COUNTIFS('Casos de prueba'!$C$2:$C$500,A24,'Casos de prueba'!$K$2:$K$500,"Aprobado") -> 34 | D24: =COUNTIFS('Casos de prueba'!$C$2:$C$500,A24,'Casos de prueba'!$K$2:$K$500,"Fallido") -> 6 | E24: =COUNTIFS('Casos de prueba'!$C$2:$C$500,A24,'Casos de prueba'!$K$2:$K$500,"Pendiente") -> 0 | F24: =COUNTIFS('Casos de prueba'!$C$2:$C$500,A24,'Casos de prueba'!$K$2:$K$500,"Bloqueado") -> 0 | G24: =IFERROR(C24/B24,0) -> 0.85
A25: Integración | B25: =COUNTIF('Casos de prueba'!$C$2:$C$500,A25) -> 8 | C25: =COUNTIFS('Casos de prueba'!$C$2:$C$500,A25,'Casos de prueba'!$K$2:$K$500,"Aprobado") -> 8 | D25: =COUNTIFS('Casos de prueba'!$C$2:$C$500,A25,'Casos de prueba'!$K$2:$K$500,"Fallido") -> 0 | E25: =COUNTIFS('Casos de prueba'!$C$2:$C$500,A25,'Casos de prueba'!$K$2:$K$500,"Pendiente") -> 0 | F25: =COUNTIFS('Casos de prueba'!$C$2:$C$500,A25,'Casos de prueba'!$K$2:$K$500,"Bloqueado") -> 0 | G25: =IFERROR(C25/B25,0) -> 1
A26: Repositorio y entrega | B26: =COUNTIF('Casos de prueba'!$C$2:$C$500,A26) -> 12 | C26: =COUNTIFS('Casos de prueba'!$C$2:$C$500,A26,'Casos de prueba'!$K$2:$K$500,"Aprobado") -> 8 | D26: =COUNTIFS('Casos de prueba'!$C$2:$C$500,A26,'Casos de prueba'!$K$2:$K$500,"Fallido") -> 3 | E26: =COUNTIFS('Casos de prueba'!$C$2:$C$500,A26,'Casos de prueba'!$K$2:$K$500,"Pendiente") -> 0 | F26: =COUNTIFS('Casos de prueba'!$C$2:$C$500,A26,'Casos de prueba'!$K$2:$K$500,"Bloqueado") -> 1 | G26: =IFERROR(C26/B26,0) -> 0.66666667
A27: Total | B27: =SUM(B20:B26) -> 165 | C27: =SUM(C20:C26) -> 150 | D27: =SUM(D20:D26) -> 13 | E27: =SUM(E20:E26) -> 0 | F27: =SUM(F20:F26) -> 2 | G27: =IFERROR(C27/B27,0) -> 0.90909091
A30: Guía de uso
A31: Celdas editables | B31: Las celdas con fondo amarillo claro se llenan al ejecutar cada caso: Estado, Resultado obtenido, Evidencia, Fecha, Responsable y Observaciones. Todos los totales de esta hoja se calculan solos.
A32: Estados | B32: Pendiente (valor inicial), Aprobado, Fallido, Bloqueado (no se pudo ejecutar por un impedimento) y No aplica (el caso no corresponde a la entrega).
A33: Ejemplo de llenado | B33: Resultado obtenido: HTTP 201, cabecera Location presente y registro visible en la base de datos. Estado: Aprobado. Evidencia: EV-API-PER-04.png. Fecha: 27/10/2026.
A34: Casos fallidos | B34: Registrar el defecto en la hoja Defectos con identificador DEF-01, DEF-02, etc., indicando el caso asociado. La fila EJEMPLO no se cuenta en los indicadores.
A35: Origen de los requisitos | B35: El enunciado formal del laboratorio no estuvo disponible. Los requisitos R01 a R12 se derivaron del reparto de roles, el documento del laboratorio, las diapositivas 8.1 y 8.2 y el DDL original en MySQL. Conviene compararlos con el enunciado oficial y ajustar la hoja Requisitos si hay diferencias.
A36: Datos de prueba | B36: Los casos que hablan de registros existentes usan los datos del DML entregado por el equipo. Si el DML cambia, deben ajustarse las claves usadas en las pruebas.

Sheet Requisitos
A1: ID | B1: Requisito | C1: Fuente | D1: Responsable | E1: Casos asociados | F1: Aprobados | G1: Fallidos | H1: Pendientes | I1: Cobertura
A2: R01 | B2: Adaptar el modelo MySQL a SQL Server: 4 tablas (persona, telefono, profesion, estudios) con claves y relaciones (DDL). | C2: Reparto de roles, ítem 1; script persona_ddl_mysql.sql | D2: Tomás | E2: =COUNTIF('Casos de prueba'!$B$2:$B$500,A2) -> 8 | F2: =COUNTIFS('Casos de prueba'!$B$2:$B$500,A2,'Casos de prueba'!$K$2:$K$500,"Aprobado") -> 6 | G2: =COUNTIFS('Casos de prueba'!$B$2:$B$500,A2,'Casos de prueba'!$K$2:$K$500,"Fallido") -> 1 | H2: =COUNTIFS('Casos de prueba'!$B$2:$B$500,A2,'Casos de prueba'!$K$2:$K$500,"Pendiente")+COUNTIFS('Casos de prueba'!$B$2:$B$500,A2,'Casos de prueba'!$K$2:$K$500,"Bloqueado") -> 1 | I2: =IF(E2=0,"Sin casos",IF(G2>0,"Con fallos",IF(F2=E2,"Cumplido","En curso"))) -> Con fallos
A3: R02 | B3: Preparar el DML con datos de prueba para las 4 tablas. | C3: Reparto de roles, ítem 1 | D3: Tomás | E3: =COUNTIF('Casos de prueba'!$B$2:$B$500,A3) -> 3 | F3: =COUNTIFS('Casos de prueba'!$B$2:$B$500,A3,'Casos de prueba'!$K$2:$K$500,"Aprobado") -> 3 | G3: =COUNTIFS('Casos de prueba'!$B$2:$B$500,A3,'Casos de prueba'!$K$2:$K$500,"Fallido") -> 0 | H3: =COUNTIFS('Casos de prueba'!$B$2:$B$500,A3,'Casos de prueba'!$K$2:$K$500,"Pendiente")+COUNTIFS('Casos de prueba'!$B$2:$B$500,A3,'Casos de prueba'!$K$2:$K$500,"Bloqueado") -> 0 | I3: =IF(E3=0,"Sin casos",IF(G3>0,"Con fallos",IF(F3=E3,"Cumplido","En curso"))) -> Cumplido
A4: R03 | B4: Configurar .NET y Entity Framework (Database First) con la cadena de conexión a SQL Server. | C4: Reparto de roles, ítem 2; diapositivas 8.1 y 8.2 | D4: Tomás | E4: =COUNTIF('Casos de prueba'!$B$2:$B$500,A4) -> 5 | F4: =COUNTIFS('Casos de prueba'!$B$2:$B$500,A4,'Casos de prueba'!$K$2:$K$500,"Aprobado") -> 4 | G4: =COUNTIFS('Casos de prueba'!$B$2:$B$500,A4,'Casos de prueba'!$K$2:$K$500,"Fallido") -> 1 | H4: =COUNTIFS('Casos de prueba'!$B$2:$B$500,A4,'Casos de prueba'!$K$2:$K$500,"Pendiente")+COUNTIFS('Casos de prueba'!$B$2:$B$500,A4,'Casos de prueba'!$K$2:$K$500,"Bloqueado") -> 0 | I4: =IF(E4=0,"Sin casos",IF(G4>0,"Con fallos",IF(F4=E4,"Cumplido","En curso"))) -> Con fallos
A5: R04 | B5: Desarrollar las interfaces y los repositorios DAO para las 4 entidades. | C5: Reparto de roles, ítem 2; documento del laboratorio, sec. 1.3 | D5: Tomás | E5: =COUNTIF('Casos de prueba'!$B$2:$B$500,A5) -> 3 | F5: =COUNTIFS('Casos de prueba'!$B$2:$B$500,A5,'Casos de prueba'!$K$2:$K$500,"Aprobado") -> 3 | G5: =COUNTIFS('Casos de prueba'!$B$2:$B$500,A5,'Casos de prueba'!$K$2:$K$500,"Fallido") -> 0 | H5: =COUNTIFS('Casos de prueba'!$B$2:$B$500,A5,'Casos de prueba'!$K$2:$K$500,"Pendiente")+COUNTIFS('Casos de prueba'!$B$2:$B$500,A5,'Casos de prueba'!$K$2:$K$500,"Bloqueado") -> 0 | I5: =IF(E5=0,"Sin casos",IF(G5>0,"Con fallos",IF(F5=E5,"Cumplido","En curso"))) -> Cumplido
A6: R05 | B6: Exponer una API REST con operaciones CRUD (GET, POST, PUT, DELETE) para las 4 entidades. | C6: Reparto de roles, ítem 3; documento del laboratorio, sec. 1.5 | D6: Tomás | E6: =COUNTIF('Casos de prueba'!$B$2:$B$500,A6) -> 44 | F6: =COUNTIFS('Casos de prueba'!$B$2:$B$500,A6,'Casos de prueba'!$K$2:$K$500,"Aprobado") -> 44 | G6: =COUNTIFS('Casos de prueba'!$B$2:$B$500,A6,'Casos de prueba'!$K$2:$K$500,"Fallido") -> 0 | H6: =COUNTIFS('Casos de prueba'!$B$2:$B$500,A6,'Casos de prueba'!$K$2:$K$500,"Pendiente")+COUNTIFS('Casos de prueba'!$B$2:$B$500,A6,'Casos de prueba'!$K$2:$K$500,"Bloqueado") -> 0 | I6: =IF(E6=0,"Sin casos",IF(G6>0,"Con fallos",IF(F6=E6,"Cumplido","En curso"))) -> Cumplido
A7: R06 | B7: Integrar Swagger para documentar y probar los endpoints. | C7: Reparto de roles, ítem 3 | D7: Tomás | E7: =COUNTIF('Casos de prueba'!$B$2:$B$500,A7) -> 9 | F7: =COUNTIFS('Casos de prueba'!$B$2:$B$500,A7,'Casos de prueba'!$K$2:$K$500,"Aprobado") -> 8 | G7: =COUNTIFS('Casos de prueba'!$B$2:$B$500,A7,'Casos de prueba'!$K$2:$K$500,"Fallido") -> 1 | H7: =COUNTIFS('Casos de prueba'!$B$2:$B$500,A7,'Casos de prueba'!$K$2:$K$500,"Pendiente")+COUNTIFS('Casos de prueba'!$B$2:$B$500,A7,'Casos de prueba'!$K$2:$K$500,"Bloqueado") -> 0 | I7: =IF(E7=0,"Sin casos",IF(G7>0,"Con fallos",IF(F7=E7,"Cumplido","En curso"))) -> Con fallos
A8: R07 | B8: Crear vistas y controladores MVC para consultar, registrar, editar y eliminar información de las 4 entidades. | C8: Reparto de roles, ítem 4; diapositivas 8.1 y 8.2 | D8: Andrés | E8: =COUNTIF('Casos de prueba'!$B$2:$B$500,A8) -> 27 | F8: =COUNTIFS('Casos de prueba'!$B$2:$B$500,A8,'Casos de prueba'!$K$2:$K$500,"Aprobado") -> 21 | G8: =COUNTIFS('Casos de prueba'!$B$2:$B$500,A8,'Casos de prueba'!$K$2:$K$500,"Fallido") -> 6 | H8: =COUNTIFS('Casos de prueba'!$B$2:$B$500,A8,'Casos de prueba'!$K$2:$K$500,"Pendiente")+COUNTIFS('Casos de prueba'!$B$2:$B$500,A8,'Casos de prueba'!$K$2:$K$500,"Bloqueado") -> 0 | I8: =IF(E8=0,"Sin casos",IF(G8>0,"Con fallos",IF(F8=E8,"Cumplido","En curso"))) -> Con fallos
A9: R08 | B9: Conectar las vistas con el backend (DAO y base de datos). | C9: Reparto de roles, ítem 5 | D9: Andrés | E9: =COUNTIF('Casos de prueba'!$B$2:$B$500,A9) -> 7 | F9: =COUNTIFS('Casos de prueba'!$B$2:$B$500,A9,'Casos de prueba'!$K$2:$K$500,"Aprobado") -> 7 | G9: =COUNTIFS('Casos de prueba'!$B$2:$B$500,A9,'Casos de prueba'!$K$2:$K$500,"Fallido") -> 0 | H9: =COUNTIFS('Casos de prueba'!$B$2:$B$500,A9,'Casos de prueba'!$K$2:$K$500,"Pendiente")+COUNTIFS('Casos de prueba'!$B$2:$B$500,A9,'Casos de prueba'!$K$2:$K$500,"Bloqueado") -> 0 | I9: =IF(E9=0,"Sin casos",IF(G9>0,"Con fallos",IF(F9=E9,"Cumplido","En curso"))) -> Cumplido
A10: R09 | B10: Respetar las relaciones entre tablas y las validaciones (p. ej. no guardar un teléfono de una persona inexistente). | C10: Documento del laboratorio, sec. 1.4 y 2.1 | D10: Equipo | E10: =COUNTIF('Casos de prueba'!$B$2:$B$500,A10) -> 46 | F10: =COUNTIFS('Casos de prueba'!$B$2:$B$500,A10,'Casos de prueba'!$K$2:$K$500,"Aprobado") -> 45 | G10: =COUNTIFS('Casos de prueba'!$B$2:$B$500,A10,'Casos de prueba'!$K$2:$K$500,"Fallido") -> 1 | H10: =COUNTIFS('Casos de prueba'!$B$2:$B$500,A10,'Casos de prueba'!$K$2:$K$500,"Pendiente")+COUNTIFS('Casos de prueba'!$B$2:$B$500,A10,'Casos de prueba'!$K$2:$K$500,"Bloqueado") -> 0 | I10: =IF(E10=0,"Sin casos",IF(G10>0,"Con fallos",IF(F10=E10,"Cumplido","En curso"))) -> Con fallos
A11: R10 | B11: Repositorio público personapi-dotnet con README, instrucciones de despliegue y TAG de entrega. | C11: Documento del laboratorio, sec. 3.8 | D11: Equipo | E11: =COUNTIF('Casos de prueba'!$B$2:$B$500,A11) -> 9 | F11: =COUNTIFS('Casos de prueba'!$B$2:$B$500,A11,'Casos de prueba'!$K$2:$K$500,"Aprobado") -> 7 | G11: =COUNTIFS('Casos de prueba'!$B$2:$B$500,A11,'Casos de prueba'!$K$2:$K$500,"Fallido") -> 1 | H11: =COUNTIFS('Casos de prueba'!$B$2:$B$500,A11,'Casos de prueba'!$K$2:$K$500,"Pendiente")+COUNTIFS('Casos de prueba'!$B$2:$B$500,A11,'Casos de prueba'!$K$2:$K$500,"Bloqueado") -> 1 | I11: =IF(E11=0,"Sin casos",IF(G11>0,"Con fallos",IF(F11=E11,"Cumplido","En curso"))) -> Con fallos
A12: R11 | B12: Documento del laboratorio con marco conceptual, diseño de la arquitectura, procedimiento, pruebas y evidencias. | C12: Reparto de roles, ítems 6 y 9 | D12: Andrés / Santiago | E12: =COUNTIF('Casos de prueba'!$B$2:$B$500,A12) -> 3 | F12: =COUNTIFS('Casos de prueba'!$B$2:$B$500,A12,'Casos de prueba'!$K$2:$K$500,"Aprobado") -> 1 | G12: =COUNTIFS('Casos de prueba'!$B$2:$B$500,A12,'Casos de prueba'!$K$2:$K$500,"Fallido") -> 2 | H12: =COUNTIFS('Casos de prueba'!$B$2:$B$500,A12,'Casos de prueba'!$K$2:$K$500,"Pendiente")+COUNTIFS('Casos de prueba'!$B$2:$B$500,A12,'Casos de prueba'!$K$2:$K$500,"Bloqueado") -> 0 | I12: =IF(E12=0,"Sin casos",IF(G12>0,"Con fallos",IF(F12=E12,"Cumplido","En curso"))) -> Con fallos
A13: R12 | B13: Cumplir las restricciones tecnológicas: ASP.NET Core MVC en .NET, Entity Framework Core y SQL Server. | C13: Documento del laboratorio, sec. 2.2 y 3.1 | D13: Equipo | E13: =COUNTIF('Casos de prueba'!$B$2:$B$500,A13) -> 1 | F13: =COUNTIFS('Casos de prueba'!$B$2:$B$500,A13,'Casos de prueba'!$K$2:$K$500,"Aprobado") -> 1 | G13: =COUNTIFS('Casos de prueba'!$B$2:$B$500,A13,'Casos de prueba'!$K$2:$K$500,"Fallido") -> 0 | H13: =COUNTIFS('Casos de prueba'!$B$2:$B$500,A13,'Casos de prueba'!$K$2:$K$500,"Pendiente")+COUNTIFS('Casos de prueba'!$B$2:$B$500,A13,'Casos de prueba'!$K$2:$K$500,"Bloqueado") -> 0 | I13: =IF(E13=0,"Sin casos",IF(G13>0,"Con fallos",IF(F13=E13,"Cumplido","En curso"))) -> Cumplido

Sheet Casos de prueba
A1: ID | B1: Req. | C1: Área | D1: Entidad | E1: Tipo | F1: Prioridad | G1: Descripción | H1: Precondición | I1: Pasos y datos de entrada | J1: Resultado esperado | K1: Estado | L1: Resultado obtenido | M1: Evidencia | N1: Fecha | O1: Responsable | P1: Observaciones
A2: BD-01 | B2: R01 | C2: Base de datos | D2: General | E2: Funcional | F2: Alta | G2: Ejecución del DDL en una instancia limpia. | H2: SQL Server disponible y sin la base persona_db. | I2: Ejecutar el script DDL completo. | J2: El script termina sin errores y crea la base persona_db. | K2: Aprobado | L2: DDL ejecutado con código 0, sin mensajes de error; persona_db creada (propietario sa). | M2: EV-BD-01.txt | N2: 46322 | O2: Automatizado | P2: Ejecutado en SQL Server 2022 en Docker con el usuario sa, según la opción A del README.
A3: BD-02 | B3: R01 | C3: Base de datos | D3: General | E3: Funcional | F3: Alta | G3: Existencia de las 4 tablas del modelo. | H3: DDL ejecutado. | I3: Consultar INFORMATION_SCHEMA.TABLES de persona_db. | J3: Existen persona, telefono, profesion y estudios. | K3: Aprobado | L3: INFORMATION_SCHEMA.TABLES lista 4 de 4 tablas en dbo: estudios, persona, profesión, teléfono. | M3: EV-BD-02.txt | N3: 46322 | O3: Automatizado
A4: BD-03 | B4: R01 | C4: Base de datos | D4: General | E4: Funcional | F4: Alta | G4: Columnas y tipos equivalentes al modelo MySQL. | H4: DDL ejecutado. | I4: Comparar columnas contra el modelo: persona(cc, nombre, apellido, genero, edad), telefono(num, oper, duenio), profesion(id, nom, des), estudios(id_prof, cc_per, fecha, univer). | J4: Todas las columnas existen con tipo equivalente; genero restringido a M o F; des admite texto largo; fecha es de tipo fecha. | K4: Aprobado | L4: 15 columnas equivalentes al modelo MySQL: INT para cc/id/duenio/cc_per, VARCHAR con las mismas longitudes, genero CHAR(1) con CHECK ('M','F'), des VARCHAR(MAX), fecha DATE. | M4: EV-BD-03.txt | N4: 46322 | O4: Automatizado | P4: ENUM de MySQL reemplazado por CHAR(1) + CHECK y TEXT por VARCHAR(MAX). Las columnas de texto son VARCHAR (no Unicode); ver BD-23.
A5: BD-04 | B5: R01 | C5: Base de datos | D5: General | E5: Funcional | F5: Alta | G5: Claves primarias del modelo. | H5: DDL ejecutado. | I5: Consultar las restricciones PRIMARY KEY de cada tabla. | J5: persona(cc), profesion(id), telefono(num) y estudios(id_prof, cc_per) como clave compuesta. | K5: Aprobado | L5: PK_persona(cc), PK_profesion(id), PK_telefono(num) y PK_estudios(id_prof, cc_per) compuesta. | M5: EV-BD-04.txt | N5: 46322 | O5: Automatizado
A6: BD-05 | B6: R01 | C6: Base de datos | D6: Telefono | E6: Funcional | F6: Alta | G6: Clave foránea telefono.duenio hacia persona.cc. | H6: DDL ejecutado. | I6: Consultar las claves foráneas de telefono. | J6: Existe la relación de telefono.duenio con persona.cc. | K6: Aprobado | L6: FK_telefono_persona: telefono.duenio -> persona.cc. | M6: EV-BD-05.txt | N6: 46322 | O6: Automatizado
A7: BD-06 | B7: R01 | C7: Base de datos | D7: Estudio | E7: Funcional | F7: Alta | G7: Claves foráneas de estudios hacia persona y profesion. | H7: DDL ejecutado. | I7: Consultar las claves foráneas de estudios. | J7: estudios.cc_per referencia persona.cc y estudios.id_prof referencia profesion.id. | K7: Aprobado | L7: FK_estudios_persona: estudios.cc_per -> persona.cc; FK_estudios_profesion: estudios.id_prof -> profesion.id. | M7: EV-BD-06.txt | N7: 46322 | O7: Automatizado
A8: BD-07 | B8: R01 | C8: Base de datos | D8: General | E8: Compatibilidad | F8: Media | G8: Ejecución del DDL en distintos entornos de SQL Server (Express, LocalDB, Docker). | H8: Al menos dos entornos disponibles. | I8: Ejecutar el mismo script DDL, sin modificarlo, en cada entorno. | J8: El script se ejecuta sin cambios manuales en cada entorno; si requiere ajustes, quedan documentados en el README. | K8: Bloqueado | L8: Docker (sa): DDL sin cambios, código 0. Login sin sysadmin: código 1, falla en ALTER AUTHORIZATION. Express y LocalDB no disponibles en macOS. | M8: EV-BD-07.txt | N8: 46322 | O8: Automatizado | P8: Solo se pudo usar un entorno real (Docker). El documento (sec. 3.2) indica que en LocalDB se ejecuto el DDL quitando ALTER AUTHORIZATION ... TO sa, y el README no documenta ese ajuste. Falta repetirlo en Windows con LocalDB o Express. Defecto DEF-05. Re-prueba ronda 2 (28/10/2026, Pull Request #9, #10 y #11): Bloqueado. Evidencia en reprueba/ronda-2/EV-R2-BD-07.*.
A9: BD-08 | B9: R01 | C9: Base de datos | D9: General | E9: Funcional | F9: Media | G9: Re-ejecución del DDL con datos ya cargados. | H9: DDL y DML ejecutados. | I9: Ejecutar de nuevo el DDL y consultar el contenido de las tablas. | J9: El comportamiento (conservar o recrear las tablas) queda documentado y el DML permite restaurar los datos de prueba. | K9: Fallido | L9: El DDL termina con código 0, hace DROP TABLE de las 4 tablas y deja 0 registros (persona 5 -> 0). El DML restaura los 20 registros. El README no advierte que se borran los datos. | M9: EV-BD-08.txt | N9: 46322 | O9: Automatizado | P9: Propuesta: advertir en el README y en el encabezado del DDL que re-ejecutarlo elimina los datos, o usar IF OBJECT_ID(...) IS NULL CREATE TABLE. Defecto DEF-04. Re-prueba ronda 2 (28/10/2026, Pull Request #9, #10 y #11): Aprobado. Evidencia en reprueba/ronda-2/EV-R2-BD-08.*.
A10: BD-09 | B10: R02 | C10: Base de datos | D10: General | E10: Funcional | F10: Alta | G10: Ejecución del DML después del DDL. | H10: DDL ejecutado. | I10: Ejecutar el script DML completo. | J10: El script termina sin errores y no viola ninguna restricción. | K10: Aprobado | L10: DML ejecutado con código 0, sin violaciones de restricciones. | M10: EV-BD-09.txt | N10: 46322 | O10: Automatizado
A11: BD-10 | B11: R02 | C11: Base de datos | D11: General | E11: Funcional | F11: Alta | G11: Datos de prueba presentes en las 4 tablas. | H11: DML ejecutado. | I11: Ejecutar SELECT COUNT(*) en cada tabla. | J11: Las 4 tablas contienen registros y las cantidades coinciden con las del DML entregado. | K11: Aprobado | L11: persona 5, profesión 4, teléfono 5, estudios 6 (20 registros), igual al DML. | M11: EV-BD-10.txt | N11: 46322 | O11: Automatizado
A12: BD-11 | B12: R02 | C12: Base de datos | D12: General | E12: Integridad | F12: Media | G12: Ausencia de registros huérfanos tras el DML. | H12: DML ejecutado. | I12: Buscar con LEFT JOIN teléfonos sin persona y estudios sin persona o profesión. | J12: No existen teléfonos ni estudios huérfanos. | K12: Aprobado | L12: 0 teléfonos y 0 estudios huérfanos. | M12: EV-BD-11.txt | N12: 46322 | O12: Automatizado
A13: BD-12 | B13: R09 | C13: Base de datos | D13: Persona | E13: Negativa | F13: Alta | G13: Campos obligatorios de persona. | H13: DML ejecutado. | I13: Insertar personas omitiendo nombre, apellido o genero, una a la vez. | J13: Cada inserción es rechazada por la restricción NOT NULL. | K13: Aprobado | L13: sin nombre: rechazado; sin apellido: rechazado; sin genero: rechazado (Msg 515, NOT NULL). | M13: EV-BD-12.txt | N13: 46322 | O13: Automatizado
A14: BD-13 | B14: R09 | C14: Base de datos | D14: Persona | E14: Negativa | F14: Alta | G14: Restricción del campo genero. | H14: DML ejecutado. | I14: Insertar una persona con genero 'X'; luego una con 'M' y otra con 'F'. | J14: 'X' es rechazado; 'M' y 'F' son aceptados. | K14: Aprobado | L14: genero X: rechazado; genero M: aceptado; genero F: aceptado (Msg 547, CK_persona_genero). | M14: EV-BD-13.txt | N14: 46322 | O14: Automatizado
A15: BD-14 | B15: R09 | C15: Base de datos | D15: Persona | E15: Límite | F15: Media | G15: Campo edad opcional y sin valores negativos. | H15: DML ejecutado. | I15: Insertar una persona con edad NULL y otra con edad -1. | J15: La edad NULL es aceptada; la edad negativa es rechazada. | K15: Aprobado | L15: edad NULL: aceptado; edad -1: rechazado (CK_persona_edad). | M15: EV-BD-14.txt | N15: 46322 | O15: Automatizado | P15: La base no limita la edad máxima; el limite 0-150 solo existe en el DTO de la API.
A16: BD-15 | B16: R09 | C16: Base de datos | D16: General | E16: Negativa | F16: Alta | G16: Claves primarias duplicadas. | H16: DML ejecutado. | I16: Insertar un registro con la misma clave de uno existente en persona, telefono y profesion. | J16: Cada inserción es rechazada por violación de clave primaria. | K16: Aprobado | L16: persona 1001: rechazado; teléfono 3001112233: rechazado; profesión 1: rechazado (Msg 2627, PRIMARY KEY). | M16: EV-BD-15.txt | N16: 46322 | O16: Automatizado
A17: BD-16 | B17: R09 | C17: Base de datos | D17: Telefono | E17: Integridad | F17: Alta | G17: Teléfono asociado a una persona inexistente. | H17: DML ejecutado. | I17: Insertar un teléfono con duenio que no existe en persona. | J17: La inserción es rechazada por la clave foránea. | K17: Aprobado | L17: duenio 999999: rechazado (Msg 547, FK_telefono_persona). | M17: EV-BD-16.txt | N17: 46322 | O17: Automatizado
A18: BD-17 | B18: R09 | C18: Base de datos | D18: Estudio | E18: Integridad | F18: Alta | G18: Estudio asociado a persona o profesión inexistente. | H18: DML ejecutado. | I18: Insertar un estudio con cc_per inexistente y otro con id_prof inexistente. | J18: Ambas inserciones son rechazadas por las claves foráneas. | K18: Aprobado | L18: cc_per inexistente: rechazado; id_prof inexistente: rechazado (Msg 547, FK de estudios). | M18: EV-BD-17.txt | N18: 46322 | O18: Automatizado
A19: BD-18 | B19: R09 | C19: Base de datos | D19: Estudio | E19: Integridad | F19: Alta | G19: Clave primaria compuesta de estudios. | H19: DML ejecutado. | I19: Insertar un estudio con el par (id_prof, cc_per) ya existente; luego una persona con otra profesión y otra persona con la misma profesión. | J19: El par duplicado es rechazado; las combinaciones nuevas son aceptadas. | K19: Aprobado | L19: par (1,1001) duplicado: rechazado; persona 1001 con profesión 2: aceptado; profesión 1 con persona 1005: aceptado. | M19: EV-BD-18.txt | N19: 46322 | O19: Automatizado
A20: BD-19 | B20: R09 | C20: Base de datos | D20: Persona | E20: Integridad | F20: Alta | G20: Eliminación de una persona con teléfonos o estudios asociados. | H20: DML ejecutado. | I20: Ejecutar DELETE sobre una persona que tiene teléfonos y estudios. | J20: La eliminación es rechazada por la clave foránea y los datos permanecen. | K20: Aprobado | L20: DELETE persona 1001: rechazado (Msg 547); la persona 1001 permanece (1 fila). | M20: EV-BD-19.txt | N20: 46322 | O20: Automatizado
A21: BD-20 | B21: R09 | C21: Base de datos | D21: Profesion | E21: Integridad | F21: Alta | G21: Eliminación de una profesión con estudios asociados. | H21: DML ejecutado. | I21: Ejecutar DELETE sobre una profesión referenciada en estudios. | J21: La eliminación es rechazada por la clave foránea. | K21: Aprobado | L21: DELETE profesión 1: rechazado (Msg 547, FK_estudios_profesion). | M21: EV-BD-20.txt | N21: 46322 | O21: Automatizado
A22: BD-21 | B22: R09 | C22: Base de datos | D22: General | E22: Funcional | F22: Media | G22: Eliminación de registros sin dependientes. | H22: DML ejecutado. | I22: Crear y eliminar un teléfono, un estudio, una profesión sin estudios y una persona sin dependientes. | J22: Todas las eliminaciones se ejecutan correctamente. | K22: Aprobado | L22: Teléfono, estudio, profesión y persona temporales creados y eliminados sin errores. | M22: EV-BD-21.txt | N22: 46322 | O22: Automatizado
A23: BD-22 | B23: R09 | C23: Base de datos | D23: General | E23: Límite | F23: Media | G23: Longitudes máximas de los campos de texto. | H23: DML ejecutado. | I23: Insertar valores de longitud máxima y máxima + 1 en nombre (45), apellido (45), nom (90), univer (50), num (15) y oper (45). | J23: La longitud máxima es aceptada; el exceso es rechazado y no se trunca en silencio. | K23: Aprobado | L23: Longitud máxima aceptada y máxima + 1 rechazada (Msg 2628, truncamiento) en los 6 campos. | M23: EV-BD-22.txt | N23: 46322 | O23: Automatizado
A24: BD-23 | B24: R09 | C24: Base de datos | D24: Persona | E24: Límite | F24: Media | G24: Almacenamiento de tildes, ñ y otros caracteres del español. | H24: DML ejecutado. | I24: Insertar y consultar nombres como 'José Muñoz' y 'Ángela Peña'. | J24: Los caracteres se guardan y se leen sin alteración. | K24: Aprobado | L24: Se guardan y leen sin alteración: José Muñoz / Ángela Peña. | M24: EV-BD-23.txt | N24: 46322 | O24: Automatizado | P24: Columnas VARCHAR con collation SQL_Latin1_General_CP1_CI_AS (código de página 1252): tildes y ñ se conservan; caracteres fuera de 1252 se alteran ('Nguyễn' -> 'Nguy?n', 'Łukasz' -> 'Lukasz'). Mejora sugerida: NVARCHAR.
A25: BD-24 | B25: R09 | C25: Base de datos | D25: Persona | E25: Límite | F25: Media | G25: Rango numérico de la cédula (cc). | H25: DML ejecutado. | I25: Insertar cc = 2147483647 y cc = 2147483648; consultar el tipo de dato y evaluar si cubre cédulas de 10 dígitos. | J25: El límite del tipo de dato queda verificado y, si no cubre las cédulas esperadas, se registra como observación del modelo. | K25: Aprobado | L25: cc 2147483647: aceptado; cc 2147483648: rechazado; cc 1014857924 (10 dígitos): aceptado. Tipo INT (máximo 2.147.483.647). | M25: EV-BD-24.txt | N25: 46322 | O25: Automatizado | P25: El INT cubre las cédulas de 10 dígitos vigentes que empiezan por 1 (hasta 1.999.999.999) y equivale al INT(15) del modelo MySQL, que también es de 32 bits. No admite valores desde 2.147.483.648; si se requieren, conviene BIGINT o VARCHAR.
A26: BD-25 | B26: R09 | C26: Base de datos | D26: Estudio | E26: Límite | F26: Baja | G26: Validez de la fecha en estudios. | H26: DML ejecutado. | I26: Insertar fechas válidas, NULL y una fecha imposible (31 de febrero). | J26: Las fechas válidas y NULL son aceptadas; la fecha imposible es rechazada. | K26: Aprobado | L26: fecha 2020-02-29: aceptado; fecha NULL: aceptado; fecha 2026-02-31: rechazado (Msg 241, conversión de fecha). | M26: EV-BD-25.txt | N26: 46322 | O26: Automatizado | P26: Control adicional: la fecha futura 2099-01-01 es aceptada; no hay CHECK sobre fecha.
A27: BK-01 | B27: R12 | C27: Backend y DAO | D27: General | E27: Revisión | F27: Alta | G27: Versión de .NET y paquetes de Entity Framework Core. | H27: Código fuente disponible. | I27: Revisar el archivo del proyecto (TargetFramework y paquetes). | J27: El proyecto usa ASP.NET Core MVC y Entity Framework Core con SQL Server; la versión de .NET queda justificada frente al enunciado. | K27: Aprobado | L27: net6.0, Microsoft.NET.Sdk.Web (ASP.NET Core MVC), EF Core 6.0.36 con SqlServer y Design, Swashbuckle 6.5.0. El README justifica .NET 6 frente al 7 del stack del enunciado. | M27: EV-BK-01.txt | N27: 46322 | O27: Automatizado | P27: .NET 6 está fuera de soporte desde noviembre de 2024; con SDK recientes se emite la advertencia NETSDK1138. Regresión en feature/frontend-mvc (eea9ee8): mismo resultado.
A28: BK-02 | B28: R03 | C28: Backend y DAO | D28: General | E28: Funcional | F28: Alta | G28: Compilación de la solución. | H28: SDK de .NET instalado. | I28: Ejecutar dotnet build sobre la solución. | J28: La compilación termina con 0 errores; las advertencias quedan registradas. | K28: Aprobado | L28: dotnet build (SDK 6.0.428): código 0, 0 errores y 0 advertencias. | M28: EV-BK-02.txt | N28: 46322 | O28: Automatizado | P28: Regresión en feature/frontend-mvc (eea9ee8): mismo resultado.
A29: BK-03 | B29: R03 | C29: Backend y DAO | D29: General | E29: Funcional | F29: Alta | G29: Arranque de la aplicación y conexión a la base de datos. | H29: Base de datos creada y cadena de conexión configurada. | I29: Ejecutar la aplicación y abrir la página de inicio y un listado. | J29: La aplicación inicia, se conecta a persona_db y muestra datos. | K29: Aprobado | L29: La aplicación inicia en http://localhost:5025; la página de inicio responde 200 y el listado de personas 200 con 5 registros de persona_db. | M29: EV-BK-03.txt | N29: 46322 | O29: Automatizado | P29: Regresión en feature/frontend-mvc (eea9ee8): mismo resultado.
A30: BK-04 | B30: R03 | C30: Backend y DAO | D30: General | E30: Revisión | F30: Alta | G30: Mapeo de las 4 entidades en el contexto de Entity Framework. | H30: Código fuente disponible. | I30: Revisar el DbContext y las clases de entidad generadas (Database First). | J30: Las 4 entidades están mapeadas, con la clave compuesta en estudios y las relaciones definidas. | K30: Aprobado | L30: persona_dbContext mapea 4 entidades (Estudio, Persona, Profesion, Telefono), clave compuesta (IdProf, CcPer) y las 3 relaciones FK_estudios_persona, FK_estudios_profesion, FK_telefono_persona. | M30: EV-BK-04.txt | N30: 46322 | O30: Automatizado | P30: El DbSet de profesión se llama 'Profesions' (pluralización del scaffold); no afecta el funcionamiento. Regresión en feature/frontend-mvc (eea9ee8): mismo resultado.
A31: BK-05 | B31: R03 | C31: Backend y DAO | D31: General | E31: Configuración | F31: Media | G31: Cadena de conexión sobrescribible sin editar el código. | H31: Aplicación compilada. | I31: Definir la cadena de conexión mediante variable de entorno o archivo de configuración local y ejecutar. | J31: La aplicación usa la cadena indicada y no es necesario modificar el código fuente. | K31: Aprobado | L31: Con ConnectionStrings__PersonaDb apuntando a otra base, la aplicación devuelve la persona 7777 (200); la instancia con appsettings.json responde 404. No se modifico código. | M31: EV-BK-05.txt | N31: 46322 | O31: Automatizado | P31: Regresión en feature/frontend-mvc (eea9ee8): mismo resultado.
A32: BK-06 | B32: R04 | C32: Backend y DAO | D32: General | E32: Revisión | F32: Alta | G32: Una interfaz DAO por entidad con sus operaciones. | H32: Código fuente disponible. | I32: Revisar las interfaces de persona, telefono, profesion y estudios. | J32: Cada interfaz declara las operaciones de consultar todos, consultar uno, verificar existencia, crear, actualizar y eliminar. | K32: Aprobado | L32: 4 interfaces (IPersona, ITelefono, IProfesion, IEstudio) con las 6 operaciones: GetAllAsync, GetByIdAsync, ExistsAsync, AddAsync, UpdateAsync, DeleteAsync. | M32: EV-BK-06.txt | N32: 46322 | O32: Automatizado | P32: Regresión en feature/frontend-mvc (eea9ee8): mismo resultado.
A33: BK-07 | B33: R04 | C33: Backend y DAO | D33: General | E33: Revisión | F33: Alta | G33: Repositorios que implementan las interfaces y se inyectan por dependencias. | H33: Código fuente disponible. | I33: Revisar las clases de repositorio y el registro de servicios al iniciar la aplicación. | J33: Existe un repositorio por interfaz, registrado en la inyección de dependencias. | K33: Aprobado | L33: 4 repositorios implementan sus interfaces y están registrados como AddScoped en Program.cs. | M33: EV-BK-07.txt | N33: 46322 | O33: Automatizado | P33: Regresión en feature/frontend-mvc (eea9ee8): mismo resultado.
A34: BK-08 | B34: R04 | C34: Backend y DAO | D34: General | E34: Revisión | F34: Media | G34: Los controladores no acceden directamente al DbContext. | H34: Código fuente disponible. | I34: Buscar referencias al DbContext en controladores MVC y REST. | J34: Los controladores dependen de las interfaces DAO y no del DbContext. | K34: Aprobado | L34: Ninguno de los 5 controladores referencia el DbContext; dependen de las interfaces DAO. | M34: EV-BK-08.txt | N34: 46322 | O34: Automatizado | P34: Regresión en feature/frontend-mvc (eea9ee8): mismo resultado.
A35: BK-09 | B35: R03 | C35: Backend y DAO | D35: General | E35: Negativa | F35: Media | G35: Comportamiento con SQL Server no disponible. | H35: Aplicación en ejecución. | I35: Detener SQL Server y solicitar un listado en la vista y en la API. | J35: La aplicación responde con un error controlado, sin mostrar detalles internos ni credenciales. | K35: Fallido | L35: La vista responde 503 con la página 'No se pudo acceder a los registros' sin detalles. La API responde 500 (text/plain; charset=utf-8) con la traza de la excepción (SqlException, at ); no expone credenciales. | M35: EV-BK-09-vista.png, EV-BK-09.txt | N35: 46322 | O35: Automatizado | P35: Ejecutado como indica el README (dotnet run, entorno Development, página de excepciones del desarrollador). En Production la API devolveria la vista HTML /Home/Error. Propuesta: manejar el error en la API con ProblemDetails (503) en todos los entornos. Defecto DEF-03. Re-prueba ronda 2 (28/10/2026, Pull Request #9, #10 y #11): Aprobado. Evidencia en reprueba/ronda-2/EV-R2-BK-09.*.
... A96: API-GEN-05 | B96: R09 | C96: API REST | D96: General | E96: Concurrencia | F96: Media | G96: Dos creaciones simultáneas con la misma clave. | H96: API en ejecución. | I96: Enviar dos POST casi simultáneos con la misma clave a un mismo recurso. | J96: Uno responde 201 y el otro 409, sin error 500 y sin registros duplicados. | K96: Fallido | L96: 20 pares de POST simultáneos: 1 con [201, 409] y 19 con un 500 en el segundo; sin registros duplicados (0). | M96: EV-API-GEN-05.txt | N96: 46322 | O96: Automatizado | P96: El POST consulta ExistsAsync y luego inserta; si ambas solicitudes pasan la consulta, la segunda falla por PK y la excepción no se controla. Propuesta: capturar DbUpdateException (error 2627) y responder 409. Regresión en feature/frontend-mvc (eea9ee8): mismo resultado. Defecto DEF-01. Re-prueba ronda 2 (28/10/2026, Pull Request #9, #10 y #11): Aprobado. Evidencia en reprueba/ronda-2/EV-R2-API-GEN-05.*.
A97: API-GEN-06 | B97: R05 | C97: API REST | D97: General | E97: Funcional | F97: Alta | G97: Persistencia de los cambios hechos por la API. | H97: Registro creado por la API. | I97: Reiniciar la aplicación y consultar el registro. | J97: El registro sigue existiendo en la base de datos. | K97: Aprobado | L97: POST 201; tras detener y reiniciar la aplicación, GET /api/personas/2090 responde 200 con los mismos datos. | M97: EV-API-GEN-06.txt | N97: 46322 | O97: Automatizado
A98: SW-01 | B98: R06 | C98: Swagger | D98: General | E98: Funcional | F98: Alta | G98: Acceso a la interfaz de Swagger. | H98: Aplicación en ejecución. | I98: Abrir la ruta /swagger en el navegador. | J98: La interfaz carga sin errores. | K98: Aprobado | L98: /swagger responde 200 y Swagger UI muestra 20 operaciones; errores de consola: 0. | M98: EV-SW-01.png | N98: 46322 | O98: Automatizado | P98: Regresión en feature/frontend-mvc (eea9ee8): mismo resultado.
A99: SW-02 | B99: R06 | C99: Swagger | D99: General | E99: Funcional | F99: Alta | G99: Documentación de los endpoints de las 4 entidades. | H99: Swagger cargado. | I99: Revisar los recursos listados. | J99: Aparecen personas, teléfonos, profesiones y estudios con GET (lista y por clave), POST, PUT y DELETE. | K99: Aprobado | L99: Personas, Telefonos, Profesiones y Estudios con GET lista, GET por clave, POST, PUT y DELETE (20 operaciones). | M99: EV-SW-02.txt | N99: 46322 | O99: Automatizado | P99: Regresión en feature/frontend-mvc (eea9ee8): mismo resultado.
A100: SW-03 | B100: R06 | C100: Swagger | D100: General | E100: Funcional | F100: Alta | G100: Ejecución de GET desde Swagger (Try it out). | H100: Swagger cargado con datos de prueba. | I100: Ejecutar GET de la lista y de un registro en cada recurso. | J100: Cada solicitud responde con el código y el cuerpo esperados. | K100: Aprobado | L100: Try it out ejecuta los 8 GET (lista y por clave de cada recurso) con respuesta 200 y cuerpo JSON. | M100: EV-SW-03.png, EV-SW-03.txt | N100: 46322 | O100: Automatizado | P100: Regresión en feature/frontend-mvc (eea9ee8): mismo resultado.
...

Sheet Defectos
A1: ID | B1: Fecha | C1: Caso(s) | D1: Req. | E1: Área | F1: Descripción del defecto | G1: Pasos para reproducir | H1: Esperado vs. obtenido | I1: Severidad | J1: Estado | K1: Responsable de corrección | L1: Evidencia | M1: Observaciones
A2: DEF-01 | B2: 46323 | C2: API-GEN-05 | D2: R09 | E2: API REST | F2: Dos POST simultáneos con la misma clave devuelven 500 en el segundo en lugar de 409. | G2: 1. Levantar main con dotnet run. 2. Enviar a la vez dos POST /api/personas con el mismo cc (p. ej. 2050). 3. Repetir 20 veces con claves distintas (QA/tests/api/api_tests.py). | H2: Esperado: 201 y 409, sin error 500. Obtenido: 201 y 500 en 20 de 20 pares; el 500 incluye la traza DbUpdateException/SqlException 2627 (PK_persona). No se crean duplicados. | I2: Media | J2: Verificado | K2: Tomás | L2: EV-API-GEN-05.txt | M2: Causa: el controlador consulta ExistsAsync y luego inserta (condición de carrera). Propuesta: capturar DbUpdateException con SqlException.Number 2627/2601 en Create y responder 409 (mismo patron que MvcControllerBase.SaveAsync). Aplica a los 4 controladores REST. Corregido por Tomás Ramírez (Pull Request #9, #10 y #11) y verificado por QA el 28/10/2026 en la re-prueba ronda 2.
A3: DEF-02 | B3: 46323 | C3: ENT-08 | D3: R10 | E3: Repositorio y entrega | F3: El comando de despliegue del README inicia la aplicación sin cadena de conexión y todas las solicitudes a datos responden 500. | G3: 1. dotnet publish personapi-dotnet/personapi-dotnet.csproj -c Release -o publish. 2. Desde la raiz: ASPNETCORE_URLS=http://localhost:5025 dotnet publish/personapi-dotnet.dll. 3. GET /api/personas. | H3: Esperado: la aplicación publicada responde igual que en desarrollo. Obtenido: 500; log: ArgumentNullException (Parameter 'connectionString'). El content root es la carpeta actual y no carga publish/appsettings.json. Desde la carpeta publish responde 200. | I3: Media | J3: Verificado | K3: Tomás | L3: EV-ENT-08.txt | M3: Propuesta: cambiar el README a 'cd publish && ASPNETCORE_URLS=... dotnet personapi-dotnet.dll' o agregar --contentRoot publish; alternativamente indicar ConnectionStrings__PersonaDb. Corregido por Tomás Ramírez (Pull Request #9, #10 y #11) y verificado por QA el 28/10/2026 en la re-prueba ronda 2.
A4: DEF-03 | B4: 46323 | C4: BK-09 | D4: R03 | E4: Backend y DAO | F4: Con SQL Server detenido, la API responde 500 con la traza completa de la excepción. | G4: 1. Ejecutar la rama feature/frontend-mvc con dotnet run (entorno Development según el README). 2. docker stop persona-sql. 3. GET /api/personas. | H4: Esperado: error controlado sin detalles internos. Obtenido: la vista responde 503 con mensaje controlado, pero la API responde 500 text/plain con SqlException y la pila de llamadas. No se exponen credenciales. | I4: Baja | J4: Verificado | K4: Tomás | L4: EV-BK-09.txt, EV-BK-09-vista.png | M4: Se presenta en Development (página de excepciones del desarrollador). Propuesta: filtro o middleware para /api que devuelva ProblemDetails 503 ante SqlException en todos los entornos, como ya hace MvcControllerBase para las vistas. Corregido por Tomás Ramírez (Pull Request #9, #10 y #11) y verificado por QA el 28/10/2026 en la re-prueba ronda 2.
A5: DEF-04 | B5: 46323 | C5: BD-08 | D5: R01 | E5: Base de datos | F5: Re-ejecutar el DDL borra las 4 tablas y sus datos sin advertencia en el README ni en el script. | G5: 1. Ejecutar 01_ddl.sql y 02_dml.sql. 2. Ejecutar de nuevo 01_ddl.sql. 3. SELECT COUNT(*) de persona. | H5: Esperado: comportamiento documentado. Obtenido: DROP TABLE de las 4 tablas, persona pasa de 5 a 0 registros; el DML restaura los datos, pero el README no lo advierte. | I5: Baja | J5: Verificado | K5: Tomás | L5: EV-BD-08.txt | M5: Propuesta: advertir en el README y en el encabezado de 01_ddl.sql que el script recrea las tablas, o crear las tablas solo si no existen. Corregido por Tomás Ramírez (Pull Request #9, #10 y #11) y verificado por QA el 28/10/2026 en la re-prueba ronda 2.
A6: DEF-05 | B6: 46323 | C6: BD-07 | D6: R01 | E6: Base de datos | F6: ALTER AUTHORIZATION ... TO sa hace fallar el DDL cuando el usuario no tiene permisos sobre sa; el README no documenta el ajuste usado en LocalDB. | G6: 1. Crear un login con rol dbcreator (sin sysadmin). 2. Ejecutar 01_ddl.sql sin cambios con ese login (QA/tests/db/bd07_entornos.py). | H6: Esperado: el script corre sin cambios o el ajuste queda documentado. Obtenido: Msg 15151 'Cannot find the principal sa...' y el DDL se detiene. El documento (sec. 3.2) indica que en LocalDB se quito esa instrucción manualmente. | I6: Baja | J6: Corregido | K6: Tomás | L6: EV-BD-07.txt | M6: No se reprodujo en LocalDB (no disponible en macOS); el fallo se reprodujo con un login sin sysadmin. Propuesta: quitar ALTER AUTHORIZATION o envolverlo en IF IS_SRVROLEMEMBER('sysadmin') = 1, y documentar LocalDB en el README. Corregido por Tomás Ramírez (Pull Request #9, #10 y #11) y comprobado por QA el 28/10/2026 solo en parte en la re-prueba ronda 2. Falta ejecutar BD-07 en Windows con SQL Server Express o LocalDB.
A7: DEF-06 | B7: 46323 | C7: MVC-PER-05, MVC-TEL-05, MVC-PRO-05, MVC-EST-05, MVC-GEN-07 | D7: R07 | E7: Frontend MVC | F7: Las claves y rutas inexistentes devuelven 404 sin contenido; el usuario ve una página en blanco o la página genérica del navegador. | G7: 1. Ejecutar feature/frontend-mvc. 2. Abrir /Personas/Details?cc=999999 o /RutaQueNoExiste/Accion. | H7: Esperado: página de no encontrado controlada. Obtenido: HTTP 404 sin cuerpo, sin layout ni enlace para volver. | I7: Baja | J7: Verificado | K7: Andrés | L7: EV-MVC-PER-05-inexistente.png, EV-MVC-GEN-07.png | M7: Propuesta: app.UseStatusCodePagesWithReExecute("/Home/Error", "?code={0}") en Program.cs y una vista de no encontrado con el layout de la aplicación. Corregido por Andrés Ortiz (Pull Request #7) y verificado por QA el 28/10/2026 en la re-prueba ronda 1.
A8: DEF-07 | B8: 46323 | C8: MVC-PER-01 | D8: R07 | E8: Frontend MVC | F8: El listado de personas no muestra la columna edad. | G8: 1. Abrir /Personas desde el menú. | H8: Esperado: columnas cc, nombre, apellido, genero y edad. Obtenido: Cédula, Nombre, Apellido, Genero y Acciones; la edad solo aparece en Detalles. | I8: Baja | J8: Verificado | K8: Andrés | L8: EV-MVC-PER-01.png | M8: El diseño de Figma (Personas · Listado) tampoco incluye la edad, asi que la omisión sigue el diseño. Propuesta: agregar <th>Edad</th> y <td>@item.Edad</td> en Views/Personas/Index.cshtml, o ajustar el caso MVC-PER-01 si el equipo mantiene el diseño. Corregido por Andrés Ortiz (Pull Request #7) y verificado por QA el 28/10/2026 en la re-prueba ronda 1.
A9: DEF-08 | B9: 46323 | C9: ENT-11 | D9: R11 | E9: Repositorio y entrega | F9: El documento conserva 8 marcadores de captura sin completar y las figuras no están numeradas. | G9: 1. Abrir el documento del laboratorio. 2. Buscar el texto '*[' y 'Figura X'. | H9: Esperado: ningún marcador pendiente y figuras numeradas. Obtenido: marcadores en las secciones 2.4, 2.5, 3.2, 3.3, 3.5, 3.6 y 3.7 (dos); los pies de figura usan 'Figura X'. | I9: Baja | J9: Abierto | K9: Andrés | L9: EV-ENT-11.txt | M9: La sección 3.9 ya incluye sus capturas. Las capturas de QA en evidencias/ (p. ej. EV-SW-01.png, EV-BD-09.txt, pantallas/EV-MVC-GEN-03-*.png) pueden usarse para los demas marcadores. Numerar las figuras y tablas al cerrar el documento.
A10: DEF-09 | B10: 46323 | C10: MVC-GEN-04 | D10: R07 | E10: Frontend MVC | F10: Los formularios de creación de personas y profesiones muestran un recuadro de error vacío antes de enviar. | G10: 1. Abrir /Personas/Create o /Profesiones/Create sin enviar datos. | H10: Esperado: sin resumen de errores hasta enviar. Obtenido: div de validación con la clase validation-summary-errors y un recuadro rojo vacío de 24 px en los tres anchos. | I10: Baja | J10: Verificado | K10: Andrés | L10: EV-MVC-GEN-04-resumen-vacio.png, EV-MVC-GEN-04.txt | M10: Hallazgo visual durante MVC-GEN-04; no impide usar el formulario. Causa probable: el GET de Create llama a ModelState.SetModelValue para dejar la clave vacía y el estado queda sin validar. Propuesta: quitar esa llamada (por ejemplo, mostrar la clave vacía con un DTO de vista con clave nullable) o renderizar el resumen solo si hay errores. Corregido por Andrés Ortiz (Pull Request #7) y verificado por QA el 28/10/2026 en la re-prueba ronda 1.
A11: DEF-10 | B11: 46323 | C11: SW-09 | D11: R06 | E11: Swagger | F11: Swagger no muestra resumenes de las operaciones ni descripciones de parametros y campos. | G11: 1. Abrir /swagger. 2. Revisar operaciones y esquemas (o swagger.json). | H11: Esperado: un tercero entiende y prueba la API sin explicacion adicional. Obtenido: 0 de 20 operaciones con resumen y 0 de 15 propiedades con descripción; campos como duenio, oper, nom o univer no se explican. | I11: Baja | J11: Verificado | K11: Tomás | L11: EV-SW-09.txt, EV-SW-01.png | M11: Propuesta: <GenerateDocumentationFile>true</GenerateDocumentationFile> en el .csproj, options.IncludeXmlComments(...) en AddSwaggerGen y comentarios /// en controladores y DTO (ya existen 4 en los DTO). Corregido por Tomás Ramírez (Pull Request #9, #10 y #11) y verificado por QA el 28/10/2026 en la re-prueba ronda 2.
A12: DEF-11 | B12: 46323 | C12: ENT-12 | D12: R11 | E12: Repositorio y entrega | F12: El documento aplica el estilo Titulo 2 a parrafos de cuerpo y sus referencias están incompletas. | G12: 1. Abrir el documento en Google Docs y revisar el esquema, los estilos de parrafo y las referencias. | H12: Esperado: formato uniforme y referencias completas. Obtenido: 38 parrafos de cuerpo con estilo Titulo 2 (aparecen en el esquema como titulos) y referencias marcadas como preliminares. | I12: Baja | J12: Abierto | K12: Andrés | L12: EV-ENT-12.txt | M12: La versión en linea ya corrigio las mayusculas de 1.2 y no menciona a Codex. Propuesta: aplicar Texto normal a los parrafos de cuerpo y un estilo de pie a las figuras, y completar las referencias en APA (ASP.NET Core MVC, EF Core, SQL Server, Swashbuckle).
